Workbook
Name AccrualsTemplate: "Button 12"
Name AcquirerAFTFees: [1]Schedules!#REF!
Name AcquirerFeeOptions: [1]Automation!#REF!
Name AcquirerOCTFees: [1]Schedules!#REF!
Name Activity: "Button 59"
Name AddressNoticeAddress: [1]Automation!#REF!
Name AFT: '[1]Dropdown Logic'!$AM$5:$AM$13
Name ApprovalRoute: '[1]MI Database Template'!$P$9:$P$14
Name dcDaysInWeek: 7
Name dcDaysInYear: 365
Name dcMthsInQtr: 3
Name dcMthsInYear: 12
Name dcQtrsInYear: 4
Name dcWeeksInYear: 52
Name DetailedOpenPurchaseOrderListing: "Button 11"
Name DetailedTransactionListings: "Button 9"
Name dMthsInYear: 12
Name FastTrack: [1]Automation!#REF!
Name GraphCumulativeSpend: "Button 5"
Name GraphPhasedSpend: "Button 3"
Name GraphYTDSpendByCategory: "Button 6"
Name HeadlineCategory: "Button 2"
Name Incentive_Options: 'P&L'!$E$109:$E$114
Name Last_Row: #N/A
Name Model: '[2]1b) Forecast Inputs '!$C$4
Name NoticeAddress: [1]Automation!#REF!
Name Number_of_Payments: #N/A
Name OCT: '[1]Dropdown Logic'!$AN$5:$AN$21
Name Payment_Date: #N/A
Name Phased: "Button 61"
Name PhasedReportsActByAccount: "Button 8"
Name Print_Area_Reset: #N/A
Name rtrtrr: #N/A
Name ss: #N/A
Name StrategicPricingPresent: [1]Automation!#REF!
Name TableName: "Dummy"
Name TM1REBUILDOPTION: 0
Name Values_Entered: #N/A
Name VersNo: 0.22
Name YTDVarianceKey: "Object 4"

Sheet Intro
A1: Model Version | C1: ='[1]Change Control'!C13 -> vMar25
B2: Please fill all cells in Yellow | D2: Opportunity ID (OPP-000XXXXXX) | E2: OPP-000989103 | F2: Deal Owner (AE) | G2: Joke Smit | H2: Scenario Name | I2: MLS | K2: Deal Checks Please ensure all checks are green | N2: Include Reason if exception
B3: Client Name | C3: RBI group | D3: Primary Market | E3: Austria | F3: Cluster | G3: =IFERROR(VLOOKUP($E$3,'[1]Deals Database'!$B$12:$C$60,2,0),"") -> Central Europe | H3: CI Ref (Finance to complete) | I3: FY26_331
B5: RBI Group, a traditional bank serving clients across multiple markets with ~7.5 million retail customers, aims to stay competitive in consumer payments. Visa made a proactive offer in FY25 to drive and support early adoption of Visa Direct to card (OCT & AFT) and Visa+ origination for consumer usecases like remittance and top ups. RBI has since provided an updated forecast and requested increased fixed support for development in FY26 and commercial rollout in FY27. The renewed proposal is designed to meet client demand, lock in solution launches across markets, drive XB performance. With this contract we'd win volume from and grow against Wise, Paypal, WeRo etc. | K5: Within Fast Track | L5: =IF(COUNTIF($L$7:$L$15,"No")>0,"No","Yes") -> Yes
B6: Alignment with VE Corporate goals: (How does this deal support VE’s corporate goals? )
B7: This approach aligns with Visa's strategic corporate goals and FY26 / FY27 scorecard by securing Visa Direct's origination penetration in the banking segment and expanding the adoption of Visa Direct value-added services such as Visa+, driving improved user experiences and driving usage. Additionally, selling Visa Direct (to Card) supports Visa's goal to diversify revenues beyond traditional consumer payments. | K7: Upfront <=$250K | L7: =IF(-SUM('P&L'!Q34:Q35)*Inputs!$O$1<=250000,"Yes","No") -> Yes
B8: Win / Retain Strategy (What is the sales strategy? - Idea of what the amount and structure of incentives & Client request?) | C8: 0 | D8: 0 | E8: 0 | F8: 0 | G8: 0 | H8: 0 | I8: 0
B9: Following Visa’s proactive FY25 offer, RBI expanded the scope to include domestic flows, revised the XB forecast, and requested higher fixed support committing to centralised development in FY26 and commercial rollout across countries in FY27 of OCT, AFT and Visa+ origination. Visa aims to secure contracting in FY26 and targets funding the fixed support through a mix of Visa Direct and CIA card‑related incentives, supported by coordinated C‑level to operational engagement. This groupdeal approach empowers RBI at central level, which is something Visa and key RBI staeholders look to establish since long. | K9: Incentive Earn-Through and Contribution B/E by Year 3 | L9: =IF(OR(SUM('P&L'!G38:I38)<=0,SUM('P&L'!G75:I75)<1),"Yes","No") -> Yes | Q9: =IF('P&L'!I49>=0,"Yes","No") -> Yes
B10: Key Benefits (What are the key reasons for approval?) | C10: 0 | D10: 0 | E10: 0 | F10: 0 | G10: 0 | H10: 0 | I10: 0
B11: Reasons for approval: this offer fits within Visa Direct fast track modelling KPI's and fast track contracting. Visa benefits are commited commercial rollout of OCT, AFT and Visa+ products with a key bank across multiple markets and growing & winning volumes against competitors like Wise. The offer stimulates XB performance through tiered transactional XB support and enhances focus on implementation and activation through milestone based fixed support that protects Visa's interests. | K11: Discount on Core Fees <=35% | L11: =IF(-'P&L'!C29<=35%,"Yes","No") -> Yes
B12: Key Commercial Concerns (What are the key concerns about this opportunity?)
B13: RBI has an remittance partnership with Wise in some markets. Not approving this deal will risk volumes going to Wise. One senior stakeholder is known to have a appreciation for Wise, which may influence internal discussions. In addition, RBI’s organisational complexity and resource constraints—similar to other large group banks such as Erste or ING—create to be expected risks in eg execution including possible shifts in timelines or scope despite Visa’s support. Tight project governance and continued alignment on scope, timelines, and resourcing will be essential to mitigate delivery risks and avoid delays. | K13: Total Incenitves excl. IRR VAT < $10M | L13: =IF(-('P&L'!Q33-'P&L'!Q39)<10000000/Inputs!O1,"Yes","No") -> Yes | N13: Provide exception why this deal should be within Fast Track
B14: What other factors should be considered? (Concerns about the client?) | C14: 0 | D14: 0 | E14: 0 | F14: 0 | G14: 0 | H14: 0 | I14: 0
B15: RBI’s geographical scale offers strong strategic upside potential for Visa, This contract will have an signal effect to other bankingclients like Erste Bank, ING. As RBI internal rules currently do not allow to do XB P2P card based payments into all XB corridors - once lifted this could lead to increased inter levels. However, capturing this deal and value requires careful navigation of their multi‑layered decision processes and expectations around support. | K15: Upfront < 25% of Total Incentives | L15: =IF(-'P&L'!Q34<=-SUM('P&L'!Q34:Q38)*0.25,"Yes","No") -> Yes
B17: Please complete the following for Contract Management: | F17: Please complete the following Client information: | K17: Please complete the following information on client's existing business:
B18: Deal Term | D18: 5 | E18: =IF(D18="","Mandatory","") | F18: Client Full Name | H18: RAIFFEISEN BANK INTERNATIONAL AG | K18: Existing CIA with the client? | N18: Yes
B19: Any existing VD portfolio under contract? | D19: No | F19: Client Address | H19: AM STADTPARK 9 | K19: PIF submitted? | N19: No
B20: If existing, when does the contract end? | D20: 47939 | E20: Ukraine only | F20: Client Notice Address | K20: Client live with VDC? | N20: Both AFT & OCT
B21: Start Date for the new deal (qtr beginning) | D21: 46296 | E21: =IF(D21="","Mandatory","") | F21: CW Number | K21: Existing OCT_L12 months (€ PV) | N21: =1589453921.49/1.1734 -> 1.3545713e+09 | O21: countries live: AT, UA, Slovakia, Kosovo, Poland, Albania,
B22: End Date for the new deal (qtr ending) | D22: =IFERROR(EOMONTH(D21-1,'P&L'!C15*12),"") -> 48121 | F22: FY Number | H22: =I3 -> FY26_331 | K22: Existing OCT_L12 months (Txn count) | N22: 33724526
B23: Break clause year (if any) | D23: 0 | F23: BID Identifier | H23: V10069913 | K23: Existing AFT_L12 months (€ PV) | N23: =2934104084.81/1.1734 -> 2.5005148e+09 | O23: countries live: AT, UA, Slovakia, Kosovo, Poland, Albania, Czech Republic
K24: Existing AFT_L12 months (Txn count) | N24: 59,876,805
B25: Microsoft Dynamics Ref (OPP-000XXXXXX) | D25: =E2 -> OPP-000989103
B26: Market Name (or Pan EU)? | D26: =Intro!E3 -> Austria
B29: Sharepoint folder link for model and VDDR deck: | E29: https://visainc.sharepoint.com/:f:/r/sites/VDWPricingTemplateGroup/Shared%20Documents/AE%20Intake%20Form%20(VDC)?csf=1&web=1&e=shDlBz
B30: Link for AFT Money Load Program | E30: https://visa.highspot.com/items/64b7ed48d004140237384d7a
B31: Link for OCT Strategic Alliance Fee Program | E31: https://visa.highspot.com/items/64b7ed7e2b4f9c04ea94b456

Sheet Inputs
A1: EEA | B1: INTRA EEA | D1: Modelling Assumptions | F1: Mandatory Fields | J1: Optional Fields | N1: FX EUR/USD | O1: 1.1734 | R1: Guidance on completing input sheet: 1. Please fill in cells highlighted in Yellow - INPUT in EUROS 2. Please select the Market from the drop down. If multiple markets, please select the biggest market for the opportunity. 3. UK/IS/CH/TK to rest of EU is Intra NON-EEA Transaction (also vice versa). If modelling for UK/IS/CH/TK, there will not be any Intra EEA transactions.
A2: UK | B2: Intra NonEEA
A3: Turkey | F3: Origin Market | G3: =VLOOKUP(Intro!$E$3,[1]Metrics!$B$114:$D$156,3,0) -> EEA | H3: Term | I3: =Intro!D18 -> 5 | N3: FX EUR/GBP | O3: 0.87268
A4: Israel | F4: Client Type | G4: Originator | H4: AFT IRF | I4: Rack | J4: Please select one option or "Rack"
A5: Switzerland | F5: =IF($G$4="Originator","Input Enabler Name","") -> Input Enabler Name | G5: self acquiring | H5: OCT IRF | I5: Rack | J5: Please select one option or "Rack"
D7: Destination | E7: Average Ticket Size
E8: OCT - PP & AA | F8: OCT - FD | G8: AFT - PP & AA | H8: AFT - FD & LA | I8: Cross Curr % | J8: Credit % | K8: Debit %
A9: =$G$3&D9 -> EEADOM | D9: DOM | E9: 208 | G9: 205 | J9: 0.5 | K9: =1-J9 -> 0.5
A10: =$G$3&D10 -> EEAINTRA EEA | D10: INTRA EEA | E10: 213 | G10: 209 | I10: 0.1 | J10: 0.5 | K10: =1-J10 -> 0.5
A11: =$G$3&D11 -> EEAINTRA Non-EEA | D11: INTRA Non-EEA | E11: 213 | G11: 209 | I11: 0.85 | J11: 0.5 | K11: =1-J11 -> 0.5
A12: =$G$3&D12 -> EEAINTER | D12: INTER | E12: 152 | G12: 150 | I12: 0.65 | J12: 0.5 | K12: =1-J12 -> 0.5
A17: Mapping Table - Do not change/delete | D17: Input Number of Transactions by Jurisdiction in Yellow Cells
E18: =IF(E19<=$I$3,1,0) -> 1 | F18: =IF(F19<=$I$3,1,0) -> 1 | G18: =IF(G19<=$I$3,1,0) -> 1 | H18: =IF(H19<=$I$3,1,0) -> 1 | I18: =IF(I19<=$I$3,1,0) -> 1 | J18: =IF(J19<=$I$3,1,0) -> 0 | K18: =IF(K19<=$I$3,1,0) -> 0 | L18: =IF(L19<=$I$3,1,0) -> 0 | ... O18: =IF(O19<=$I$3,1,0) -> 0
D19: OCT - PP & AA | E19: 1 | F19: 2 | G19: 3 | H19: 4 | I19: 5 | J19: 6 | K19: 7 | L19: 8 | M19: 9 | N19: 10 | O19: Total
D20: Total PV | E20: =SUM(E21:E25) -> 1.4922475e+08 | F20: =SUM(F21:F25) -> 2.3936609e+08 | G20: =SUM(G21:G25) -> 3.9076264e+08 | H20: =SUM(H21:H25) -> 5.5191315e+08 | I20: =SUM(I21:I25) -> 8.0713376e+08 | J20: =SUM(J21:J25) -> 0 | K20: =SUM(K21:K25) -> 0 | L20: =SUM(L21:L25) -> 0 | ... N20: =SUM(N21:N25) -> 0 | O20: =SUM(E20:N20) -> 2.1384004e+09
D21: DOM | E21: =E28*$E9 -> 1.2259826e+08 | F21: =F28*$E9 -> 1.7614036e+08 | G21: =G28*$E9 -> 2.5265703e+08 | H21: =H28*$E9 -> 3.5685278e+08 | I21: =I28*$E9 -> 5.0693678e+08 | J21: =J28*$E9 -> 0 | K21: =K28*$E9 -> 0 | L21: =L28*$E9 -> 0 | ... N21: =N28*$E9 -> 0 | O21: =SUM(E21:N21) -> 1.4151852e+09
D22: INTRA EEA - Euro | E22: =E29*$E10 -> 0 | F22: =F29*$E10 -> 0 | G22: =G29*$E10 -> 0 | H22: =H29*$E10 -> 0 | I22: =I29*$E10 -> 0 | J22: =J29*$E10 -> 0 | K22: =K29*$E10 -> 0 | L22: =L29*$E10 -> 0 | ... N22: =N29*$E10 -> 0 | O22: =SUM(E22:N22) -> 0
D23: INTRA EEA - non Euro | E23: =E30*$E10 -> 0 | F23: =F30*$E10 -> 0 | G23: =G30*$E10 -> 0 | H23: =H30*$E10 -> 0 | I23: =I30*$E10 -> 0 | J23: =J30*$E10 -> 0 | K23: =K30*$E10 -> 0 | L23: =L30*$E10 -> 0 | ... N23: =N30*$E10 -> 0 | O23: =SUM(E23:N23) -> 0
D24: INTRA Non-EEA | E24: =E31*$E11 -> 5089381.2 | F24: =F31*$E11 -> 8386282.3 | G24: =G31*$E11 -> 14100935 | H24: =H31*$E11 -> 19916160 | I24: =I31*$E11 -> 29301651 | J24: =J31*$E11 -> 0 | K24: =K31*$E11 -> 0 | L24: =L31*$E11 -> 0 | ... N24: =N31*$E11 -> 0 | O24: =SUM(E24:N24) -> 76794409
D25: INTER | E25: =E32*$E12 -> 21537105 | F25: =F32*$E12 -> 54839443 | G25: =G32*$E12 -> 1.2400468e+08 | H25: =H32*$E12 -> 1.7514421e+08 | I25: =I32*$E12 -> 2.7089532e+08 | J25: =J32*$E12 -> 0 | K25: =K32*$E12 -> 0 | L25: =L32*$E12 -> 0 | ... N25: =N32*$E12 -> 0 | O25: =SUM(E25:N25) -> 6.4642075e+08
F26: =F27/E27-1 -> 0.65163801 | G26: =G27/F27-1 -> 0.68142857 | H26: =H27/G27-1 -> 0.4124 | I26: =I27/H27-1 -> 0.47125 | R26: Choose Main and Detailed Use Case for OCT P2P | T26: Secondary (BAI) | U26: Tertiary BAI
D27: Total Transactions | E27: =SUM(E28:E32) -> 755000 | F27: =SUM(F28:F32) -> 1246986.7 | G27: =SUM(G28:G32) -> 2096719.1 | H27: =SUM(H28:H32) -> 2961406 | I27: =SUM(I28:I32) -> 4356968.6 | J27: =SUM(J28:J32) -> 0 | K27: =SUM(K28:K32) -> 0 | L27: =SUM(L28:L32) -> 0 | ... N27: =SUM(N28:N32) -> 0 | O27: =SUM(E27:N27) -> 11417080 | P27: =O27/SUM($O$27+$O$42+$O$57) -> 0.76923077
A28: =$G$3&$D$19&D28 -> EEAOCT - PP & AADOM | B28: DOM | D28: DOM | E28: 589414.71 | F28: 846828.67 | G28: 1214697.2 | H28: 1715638.4 | I28: 2437196.1 | O28: =SUM(E28:N28) -> 6803775.1 | R28: Remittances | S28: XB P2P (Back-to-back) | T28: PP | U28: AA
A29: =$G$3&$D$19&D29 -> EEAOCT - PP & AAINTRA EEA - Euro | B29: INTRA EEA - Euro | D29: INTRA EEA - Euro | O29: =SUM(E29:N29) -> 0
A30: =$G$3&$D$19&D30 -> EEAOCT - PP & AAINTRA EEA - non Euro | B30: INTRA EEA - non Euro | D30: INTRA EEA - non Euro | O30: =SUM(E30:N30) -> 0
A31: =$G$3&$D$19&D31 -> EEAOCT - PP & AAINTRA Non-EEA | B31: INTRA Non-EEA | D31: INTRA Non-EEA | E31: 23893.808 | F31: 39372.217 | G31: 66201.571 | H31: 93503.099 | I31: 137566.43 | O31: =SUM(E31:N31) -> 360537.13 | R31: Remittances | S31: XB P2P (Back-to-back) | T31: PP | U31: AA
A32: =$G$3&$D$19&D32 -> EEAOCT - PP & AAINTER | B32: INTER | D32: INTER | E32: 141691.48 | F32: 360785.81 | G32: 815820.25 | H32: 1152264.5 | I32: 1782206.1 | O32: =SUM(E32:N32) -> 4252768.1 | R32: Remittances | S32: XB P2P (Back-to-back) | T32: PP | U32: AA
D34: OCT - FD | E34: 1 | F34: 2 | G34: 3 | H34: 4 | I34: 5 | J34: 6 | K34: 7 | L34: 8 | M34: 9 | N34: 10 | O34: Total | R34: Remittances | S34: XB P2P (Back-to-back) | T34: PP | U34: AA
D35: Total PV | E35: =SUM(E36:E40) -> 0 | F35: =SUM(F36:F40) -> 0 | G35: =SUM(G36:G40) -> 0 | H35: =SUM(H36:H40) -> 0 | I35: =SUM(I36:I40) -> 0 | J35: =SUM(J36:J40) -> 0 | K35: =SUM(K36:K40) -> 0 | L35: =SUM(L36:L40) -> 0 | ... N35: =SUM(N36:N40) -> 0 | O35: =SUM(E35:N35) -> 0 | R35: Remittances | S35: XB Funds Transfer (Send funds to receiver only) | T35: PP | U35: AA
D36: DOM | E36: =E43*$F9 -> 0 | F36: =F43*$F9 -> 0 | G36: =G43*$F9 -> 0 | H36: =H43*$F9 -> 0 | I36: =I43*$F9 -> 0 | J36: =J43*$F9 -> 0 | K36: =K43*$F9 -> 0 | L36: =L43*$F9 -> 0 | ... N36: =N43*$F9 -> 0 | O36: =SUM(E36:N36) -> 0 | R36: Person2Person(P2P) | S36: XB P2P (Back-to-back) | T36: PP | U36: AA
D37: INTRA EEA - Euro | E37: =E44*$F10 -> 0 | F37: =F44*$F10 -> 0 | G37: =G44*$F10 -> 0 | H37: =H44*$F10 -> 0 | I37: =I44*$F10 -> 0 | J37: =J44*$F10 -> 0 | K37: =K44*$F10 -> 0 | L37: =L44*$F10 -> 0 | ... N37: =N44*$F10 -> 0 | O37: =SUM(E37:N37) -> 0 | R37: Person2Person(P2P) | S37: Wallet Transfers | T37: WT
D38: INTRA EEA - non Euro | E38: =E45*$F10 -> 0 | F38: =F45*$F10 -> 0 | G38: =G45*$F10 -> 0 | H38: =H45*$F10 -> 0 | I38: =I45*$F10 -> 0 | J38: =J45*$F10 -> 0 | K38: =K45*$F10 -> 0 | L38: =L45*$F10 -> 0 | ... N38: =N45*$F10 -> 0 | O38: =SUM(E38:N38) -> 0 | R38: Person2Person(P2P) | S38: Money Transfers
D39: INTRA Non-EEA | E39: =E46*$F11 -> 0 | F39: =F46*$F11 -> 0 | G39: =G46*$F11 -> 0 | H39: =H46*$F11 -> 0 | I39: =I46*$F11 -> 0 | J39: =J46*$F11 -> 0 | K39: =K46*$F11 -> 0 | L39: =L46*$F11 -> 0 | ... N39: =N46*$F11 -> 0 | O39: =SUM(E39:N39) -> 0
D40: INTER | E40: =E47*$F12 -> 0 | F40: =F47*$F12 -> 0 | G40: =G47*$F12 -> 0 | H40: =H47*$F12 -> 0 | I40: =I47*$F12 -> 0 | J40: =J47*$F12 -> 0 | K40: =K47*$F12 -> 0 | L40: =L47*$F12 -> 0 | ... N40: =N47*$F12 -> 0 | O40: =SUM(E40:N40) -> 0
R41: Choose Main and Detailed Use Case for OCT FD | T41: Secondary (BAI) | U41: Tertiary BAI
D42: Total Transactions | E42: =SUM(E43:E47) -> 0 | F42: =SUM(F43:F47) -> 0 | G42: =SUM(G43:G47) -> 0 | H42: =SUM(H43:H47) -> 0 | I42: =SUM(I43:I47) -> 0 | J42: =SUM(J43:J47) -> 0 | K42: =SUM(K43:K47) -> 0 | L42: =SUM(L43:L47) -> 0 | ... N42: =SUM(N43:N47) -> 0 | O42: =SUM(E42:N42) -> 0 | P42: =O42/SUM($O$27+$O$42+$O$57) -> 0
A43: =$G$3&$D$34&D43 -> EEAOCT - FDDOM | B43: DOM | D43: DOM | O43: =SUM(E43:N43) -> 0
A44: =$G$3&$D$34&D44 -> EEAOCT - FDINTRA EEA - Euro | B44: INTRA EEA - Euro | D44: INTRA EEA - Euro | O44: =SUM(E44:N44) -> 0
A45: =$G$3&$D$34&D45 -> EEAOCT - FDINTRA EEA - non Euro | B45: INTRA EEA - non Euro | D45: INTRA EEA - non Euro | O45: =SUM(E45:N45) -> 0
A46: =$G$3&$D$34&D46 -> EEAOCT - FDINTRA Non-EEA | B46: INTRA Non-EEA | D46: INTRA Non-EEA | O46: =SUM(E46:N46) -> 0
...

Sheet P&L
F2: Option 2 (Only XB OCTs, tiered discount) | G2: 0.03 | H2: Option 1: Flat % discount on all core OCT fees (AFTs excluded), Max 35%. For small deals cap at 25% | J2: Option 2: Tiered XB Discount on XB OCTs only (refer to tiering Table) - standard tier table | L2: Option 3: Tiered % Discount on All OCTs, tiering by DOM/Intra and XB | N2: Enterprie Adj. AANR | O2: =(Q41+Q47)/Intro!D18 -> 1224739 | P2: =O2*Inputs!O1 -> 1437108.8 | Q2: EU VD Only Adj. AANR | R2: =SUM(Q19:Q25,Q31,Q33,Q47)/Intro!D18 -> 704788.49 | S2: =R2*Inputs!O1 -> 826998.82
F3: OCT Txn % | G3: =IFERROR(1-G4,"") -> 0.76923077 | H3: =IFERROR(1-H4,"") -> 0.76923077 | I3: =IFERROR(1-I4,"") -> 0.76923077 | J3: =IFERROR(1-J4,"") -> 0.76923077 | K3: =IFERROR(1-K4,"") -> 0.76923077 | L3: =IFERROR(1-L4,"") | M3: =IFERROR(1-M4,"") | N3: =IFERROR(1-N4,"") | P3: =IFERROR(1-P4,"")
C4: =IFERROR(IF(AND(Intro!D22<>"", Intro!D21<>"", C15<>""), IF(ABS(DATEDIF(Intro!D21,Intro!D22,"D") - C15*365.25) > 5, "DATE ERROR",""),""),"Check Start/End Qtr") | F4: AFT Txn % | G4: =IFERROR(Inputs!E57/Inputs!E84,"") -> 0.23076923 | H4: =IFERROR(Inputs!F57/Inputs!F84,"") -> 0.23076923 | I4: =IFERROR(Inputs!G57/Inputs!G84,"") -> 0.23076923 | J4: =IFERROR(Inputs!H57/Inputs!H84,"") -> 0.23076923 | K4: =IFERROR(Inputs!I57/Inputs!I84,"") -> 0.23076923 | L4: =IFERROR(Inputs!J57/Inputs!J84,"") | M4: =IFERROR(Inputs!K57/Inputs!K84,"") | N4: =IFERROR(Inputs!L57/Inputs!L84,"") | ... Q4: =IFERROR(Inputs!O57/Inputs!O84,"") -> 0.23076923
F5: Total | G5: 1 | H5: 2 | I5: 3 | J5: 4 | K5: 5 | L5: 6 | M5: 7 | N5: 8 | O5: 9 | P5: 10 | Q5: Total
F6: PV - Total EUROS | G6: =Inputs!E78 -> 1.9574785e+08 | H6: =Inputs!F78 -> 3.1620541e+08 | I6: =Inputs!G78 -> 5.1996247e+08 | J6: =Inputs!H78 -> 7.3439499e+08 | K6: =Inputs!I78 -> 1.0756102e+09 | L6: =Inputs!J78 -> 0 | M6: =Inputs!K78 -> 0 | N6: =Inputs!L78 -> 0 | ... P6: =Inputs!N78 -> 0 | Q6: =SUM(G6:P6) -> 2.8419209e+09 | S6: =Q6=Q9+Q12+Q15 -> TRUE
F7: Transactions - Total | G7: =Inputs!E84 -> 981500 | H7: =Inputs!F84 -> 1621082.7 | I7: =Inputs!G84 -> 2725734.8 | J7: =Inputs!H84 -> 3849827.8 | K7: =Inputs!I84 -> 5664059.1 | L7: =Inputs!J84 -> 0 | M7: =Inputs!K84 -> 0 | N7: =Inputs!L84 -> 0 | ... P7: =Inputs!N84 -> 0 | Q7: =SUM(G7:P7) -> 14842204 | S7: =Q7=Q10+Q13+Q16 -> TRUE
E9: PV and Volumes | F9: PV - EU Dom | G9: =Inputs!E79 -> 1.6438751e+08 | H9: =Inputs!F79 -> 2.4516108e+08 | I9: =Inputs!G79 -> 3.6871042e+08 | J9: =Inputs!H79 -> 5.207666e+08 | K9: =Inputs!I79 -> 7.48095e+08 | L9: =Inputs!J79 -> 0 | M9: =Inputs!K79 -> 0 | N9: =Inputs!L79 -> 0 | ... P9: =Inputs!N79 -> 0 | Q9: =SUM(G9:P9) -> 2.0471206e+09 | S9: =Q9=Inputs!O79 -> TRUE
F10: Transactions - EU Dom | G10: =Inputs!E85 -> 793264.71 | H10: =Inputs!F85 -> 1183515.1 | I10: =Inputs!G85 -> 1780811.4 | J10: =Inputs!H85 -> 2515218 | K10: =Inputs!I85 -> 3613577.6 | L10: =Inputs!J85 -> 0 | M10: =Inputs!K85 -> 0 | N10: =Inputs!L85 -> 0 | ... P10: =Inputs!N85 -> 0 | Q10: =SUM(G10:P10) -> 9886386.8 | S10: =Q10=Inputs!O85 -> TRUE
F12: PV - EU Intra EEA + Non-EEA | G12: =SUM(Inputs!E80:E81) -> 9823231.2 | H12: =SUM(Inputs!F80:F81) -> 16204889 | I12: =SUM(Inputs!G80:G81) -> 27247363 | J12: =SUM(Inputs!H80:H81) -> 38484176 | K12: =SUM(Inputs!I80:I81) -> 56619843 | L12: =SUM(Inputs!J80:J81) -> 0 | M12: =SUM(Inputs!K80:K81) -> 0 | N12: =SUM(Inputs!L80:L81) -> 0 | ... P12: =SUM(Inputs!N80:N81) -> 0 | Q12: =SUM(G12:P12) -> 1.483795e+08 | S12: =Q12=Inputs!O80+Inputs!O81 -> TRUE
F13: Transactions - EU Intra EEA + Non-EEA | G13: =SUM(Inputs!E86:E87) -> 46543.808 | H13: =SUM(Inputs!F86:F87) -> 76781.818 | I13: =SUM(Inputs!G86:G87) -> 129103.14 | J13: =SUM(Inputs!H86:H87) -> 182345.28 | K13: =SUM(Inputs!I86:I87) -> 268275.49 | L13: =SUM(Inputs!J86:J87) -> 0 | M13: =SUM(Inputs!K86:K87) -> 0 | N13: =SUM(Inputs!L86:L87) -> 0 | ... P13: =SUM(Inputs!N86:N87) -> 0 | Q13: =SUM(G13:P13) -> 703049.54 | S13: =Q13=Inputs!O86+Inputs!O87 -> TRUE
B14: Deal KPIs (EUROS)
B15: Term of Contract (years) | C15: =Inputs!I3 -> 5 | F15: PV - XB | G15: =Inputs!E82 -> 21537105 | H15: =Inputs!F82 -> 54839443 | I15: =Inputs!G82 -> 1.2400468e+08 | J15: =Inputs!H82 -> 1.7514421e+08 | K15: =Inputs!I82 -> 2.7089532e+08 | L15: =Inputs!J82 -> 0 | M15: =Inputs!K82 -> 0 | N15: =Inputs!L82 -> 0 | ... P15: =Inputs!N82 -> 0 | Q15: =SUM(G15:P15) -> 6.4642075e+08 | S15: =Q15=Inputs!O82 -> TRUE
B16: Total Transactions | C16: =Inputs!O84 -> 14842204 | F16: Transactions - XB | G16: =Inputs!E88 -> 141691.48 | H16: =Inputs!F88 -> 360785.81 | I16: =Inputs!G88 -> 815820.25 | J16: =Inputs!H88 -> 1152264.5 | K16: =Inputs!I88 -> 1782206.1 | L16: =Inputs!J88 -> 0 | M16: =Inputs!K88 -> 0 | N16: =Inputs!L88 -> 0 | ... P16: =Inputs!N88 -> 0 | Q16: =SUM(G16:P16) -> 4252768.1 | S16: =Q16=Inputs!O88 -> TRUE
B17: Average Annualised Tranactions | C17: =IFERROR(C16/C15,0) -> 2968440.9
B18: DOM Txn% | C18: =IFERROR(Inputs!P80,"check") -> 0.66609962 | E18: Fees/revenue | F18: Gross Revenue (OCT+AFT) | G18: =SUM(G19:G32) -> 280593.61 | H18: =SUM(H19:H32) -> 703491.34 | I18: =SUM(I19:I32) -> 1394696.8 | J18: =SUM(J19:J32) -> 1861674.8 | K18: =SUM(K19:K32) -> 2846225.9 | L18: =SUM(L19:L32) -> 0 | M18: =SUM(M19:M32) -> 0 | N18: =SUM(N19:N32) -> 0 | ... P18: =SUM(P19:P32) -> 0 | Q18: =SUM(G18:P18) -> 7086682.5
B19: INTRA EEA Txn% | C19: =IFERROR(Inputs!P81,"check") -> 0 | F19: Acq Processing Rev - EU Dom | G19: =[1]Calcs!AY103 -> 835.785 | H19: =[1]Calcs!AZ103 -> 1380.4143 | I19: =[1]Calcs!BA103 -> 2321.068 | J19: =[1]Calcs!BB103 -> 3278.2764 | K19: =[1]Calcs!BC103 -> 4823.1642 | L19: =[1]Calcs!BD103 -> 0 | M19: =[1]Calcs!BE103 -> 0 | N19: =[1]Calcs!BF103 -> 0 | ... P19: =[1]Calcs!BH103 -> 0 | Q19: =SUM(G19:P19) -> 12638.708
B20: INTRA Non-EEA Txn% | C20: =IFERROR(Inputs!P82,"check") -> 0.04736827 | F20: Acq Scheme Rev - EU Dom | G20: =[1]Calcs!AN103 -> 19813.447 | H20: =[1]Calcs!AO103 -> 30824.576 | I20: =[1]Calcs!AP103 -> 48691.552 | J20: =[1]Calcs!AQ103 -> 68771.949 | K20: =[1]Calcs!AR103 -> 99876.676 | L20: =[1]Calcs!AS103 -> 0 | M20: =[1]Calcs!AT103 -> 0 | N20: =[1]Calcs!AU103 -> 0 | ... P20: =[1]Calcs!AW103 -> 0 | Q20: =SUM(G20:P20) -> 267978.2
B21: Inter Txn% | C21: =IFERROR(Inputs!P83,"check") -> 0.28653211
B22: Total Core Acquiring Fees | C22: =SUM(G19:P25) -> 4433619.5 | F22: Acq Processing Rev - EU Intra | G22: =[1]Calcs!AY104 -> 0 | H22: =[1]Calcs!AZ104 -> 0 | I22: =[1]Calcs!BA104 -> 0 | J22: =[1]Calcs!BB104 -> 0 | K22: =[1]Calcs!BC104 -> 0 | L22: =[1]Calcs!BD104 -> 0 | M22: =[1]Calcs!BE104 -> 0 | N22: =[1]Calcs!BF104 -> 0 | ... P22: =[1]Calcs!BH104 -> 0 | Q22: =SUM(G22:P22) -> 0
B23: Total Gross Revenue | C23: =Q18 -> 7086682.5 | F23: Acq Scheme Rev - EU Intra | G23: =[1]Calcs!AN104 -> 0 | H23: =[1]Calcs!AO104 -> 0 | I23: =[1]Calcs!AP104 -> 0 | J23: =[1]Calcs!AQ104 -> 0 | K23: =[1]Calcs!AR104 -> 0 | L23: =[1]Calcs!AS104 -> 0 | M23: =[1]Calcs!AT104 -> 0 | N23: =[1]Calcs!AU104 -> 0 | ... P23: =[1]Calcs!AW104 -> 0 | Q23: =SUM(G23:P23) -> 0
B24: Total Incentives incl IRR VAT | C24: =Q33 -> -850487.43
B25: Total Net Revenue | C25: =IFERROR(Q41,0) -> 6236195.1 | F25: Acquirer Rev - XB (Inter + Intra non EEA) | G25: =SUM([1]Calcs!AN105:AN106,[1]Calcs!AY105:AY106) -> 156748.7 | H25: =SUM([1]Calcs!AO105:AO106,[1]Calcs!AZ105:AZ106) -> 365934.07 | I25: =SUM([1]Calcs!AP105:AP106,[1]Calcs!BA105:BA106) -> 792099.58 | J25: =SUM([1]Calcs!AQ105:AQ106,[1]Calcs!BB105:BB106) -> 1118761.5 | K25: =SUM([1]Calcs!AR105:AR106,[1]Calcs!BC105:BC106) -> 1719458.8 | L25: =SUM([1]Calcs!AS105:AS106,[1]Calcs!BD105:BD106) -> 0 | M25: =SUM([1]Calcs!AT105:AT106,[1]Calcs!BE105:BE106) -> 0 | N25: =SUM([1]Calcs!AU105:AU106,[1]Calcs!BF105:BF106) -> 0 | ... P25: =SUM([1]Calcs!AW105:AW106,[1]Calcs!BH105:BH106) -> 0 | Q25: =SUM(G25:P25) -> 4153002.6 | S25: =SUM(Q20:Q25) -> 4420980.8
B26: AANR | C26: =IFERROR(C25/C15,0) -> 1247239 | F26: Issuer Rev (All Volumes) | G26: =G73 -> 8710.5371 | H26: =H73 -> 11761.468 | I26: =I73 -> 16036.29 | J26: =J73 -> 20384.691 | K26: =K73 -> 26398.67 | L26: =L73 -> 0 | M26: =M73 -> 0 | N26: =N73 -> 0 | ... P26: =P73 -> 0 | Q26: =SUM(G26:P26) -> 83291.657
B27: AANR excl VTS | C27: =(Q41-Q32)/C15 -> 1240388.8 | F27: Other Fees (e.g. Alias Directory) | Q27: =SUM(G27:P27) -> 0
B28: Incentive $ of Gross Rev. incl VAT | C28: =IFERROR(C24/C23,0) -> -0.12001207 | F28: VIK Revenues | G28: =-SUM(G35,G37) -> 0 | H28: =-SUM(H35,H37) -> 75000 | I28: =-SUM(I35,I37) -> 75000 | J28: =-SUM(J35,J37) -> 0 | K28: =-SUM(K35,K37) -> 0 | L28: =-SUM(L35,L37) -> 0 | M28: =-SUM(M35,M37) -> 0 | N28: =-SUM(N35,N37) -> 0 | ... P28: =-SUM(P35,P37) -> 0 | Q28: =SUM(G28:P28) -> 150000
B29: Incentive $ of Core Fees excl IRR VAT | C29: =IFERROR((C24-Q39)/C22,0) -> -0.1875684 | F29: FX Spread - Inter | G29: =[1]Calcs!BJ106 -> 62996.031 | H29: =[1]Calcs!BK106 -> 160405.37 | I29: =[1]Calcs!BL106 -> 362713.68 | J29: =[1]Calcs!BM106 -> 512296.8 | K29: =[1]Calcs!BN106 -> 792368.81 | L29: =[1]Calcs!BO106 -> 0 | M29: =[1]Calcs!BP106 -> 0 | N29: =[1]Calcs!BQ106 -> 0 | ... P29: =[1]Calcs!BS106 -> 0 | Q29: =SUM(G29:P29) -> 1890780.7
B30: IRR VAT Rate | C30: 0.0277 | F30: FX Spread - Intra | G30: =[1]Calcs!BJ104+[1]Calcs!BJ105 -> 29224.113 | H30: =[1]Calcs!BK104+[1]Calcs!BK105 -> 48209.544 | I30: =[1]Calcs!BL104+[1]Calcs!BL105 -> 81060.905 | J30: =[1]Calcs!BM104+[1]Calcs!BM105 -> 114490.42 | K30: =[1]Calcs!BN104+[1]Calcs!BN105 -> 168444.03 | L30: =[1]Calcs!BO104+[1]Calcs!BO105 -> 0 | M30: =[1]Calcs!BP104+[1]Calcs!BP105 -> 0 | N30: =[1]Calcs!BQ104+[1]Calcs!BQ105 -> 0 | ... P30: =[1]Calcs!BS104+[1]Calcs!BS105 -> 0 | Q30: =SUM(G30:P30) -> 441429.02
B31: IRR VAT Rate | C31: 0.0277 | F31: Visa+ | H31: =SUM(Inputs!F27,Inputs!F42)*[1]Calcs!$B$4*0.5 -> 6234.9335 | I31: =SUM(Inputs!G27,Inputs!G42)*[1]Calcs!$B$4*0.5 -> 10483.595 | J31: =SUM(Inputs!H27,Inputs!H42)*[1]Calcs!$B$4*0.5 -> 14807.03 | K31: =SUM(Inputs!I27,Inputs!I42)*[1]Calcs!$B$4*0.5 -> 21784.843 | L31: =SUM(Inputs!J27,Inputs!J42)*[1]Calcs!$B$4*0.5 -> 0 | M31: =SUM(Inputs!K27,Inputs!K42)*[1]Calcs!$B$4*0.5 -> 0 | N31: =SUM(Inputs!L27,Inputs!L42)*[1]Calcs!$B$4*0.5 -> 0 | O31: =SUM(Inputs!M27,Inputs!M42)*[1]Calcs!$B$4*0.5 -> 0 | P31: =SUM(Inputs!N27,Inputs!N42)*[1]Calcs!$B$4*0.5 -> 0 | Q31: =SUM(G31:P31) -> 53310.402 | R31: Visa+ fee waived until 2027
B32: Deal Breakeven | C32: =Q75 -> 1 | F32: Delegated Auth Fees (3DS/VTS) | G32: =SUM(Inputs!E57,Inputs!E71)*[1]Calcs!$B$3 -> 2265 | H32: =SUM(Inputs!F57,Inputs!F71)*[1]Calcs!$B$3 -> 3740.9601 | I32: =SUM(Inputs!G57,Inputs!G71)*[1]Calcs!$B$3 -> 6290.1572 | J32: =SUM(Inputs!H57,Inputs!H71)*[1]Calcs!$B$3 -> 8884.218 | K32: =SUM(Inputs!I57,Inputs!I71)*[1]Calcs!$B$3 -> 13070.906 | L32: =SUM(Inputs!J57,Inputs!J71)*[1]Calcs!$B$3 -> 0 | M32: =SUM(Inputs!K57,Inputs!K71)*[1]Calcs!$B$3 -> 0 | N32: =SUM(Inputs!L57,Inputs!L71)*[1]Calcs!$B$3 -> 0 | ... P32: =SUM(Inputs!N57,Inputs!N71)*[1]Calcs!$B$3 -> 0 | Q32: =SUM(G32:P32) -> 34251.241
B33: Upfront | C33: =Q34+Q35 -> -45000 | E33: Incentives | F33: Total Incentives (incl VAT) | G33: =SUM(G34:G39) -> -46246.5 | H33: =SUM(H34:H39) -> -75000 | I33: =SUM(I34:I39) -> -82075.163 | J33: =SUM(J34:J39) -> -221300.75 | K33: =SUM(K34:K39) -> -425865.02 | L33: =SUM(L34:L39) -> 0 | M33: =SUM(M34:M39) -> 0 | N33: =SUM(N34:N39) -> 0 | ... Q33: =SUM(Q34:Q39) -> -850487.43 | R33: =Q33/Q18 -> -0.12001207 | S33: =Q33/SUM(Q19:Q25) -> -0.19182689
B34: Fixed Support | C34: =Q36+Q37 -> -150000 | F34: Upfront Cash - earned out | G34: -45000 | Q34: =SUM(G34:P34) -> -45000 | R34: end of 2027
F35: Upfront VIK (Gross, including VAT) - earned out | Q35: =SUM(G35:P35) -> 0
B36: Volume Support | C36: =Q38 -> -636606.92 | F36: Fixed Support - earned out | Q36: =SUM(G36:P36) -> 0
B37: Total Incentive Value | C37: =SUM(C33:C36) -> -831606.92 | F37: VIK Support (Gross, including VAT) - earned out | H37: -75000 | I37: -75000 | Q37: =SUM(G37:P37) -> -150000
B38: Please review the RED cells as these indicate an error | F38: Volume Support (milestone based) | G38: =IF(SUM($G$117:G117)-SUM($G34:G$37)>0,0,SUM($G$117:G117)-SUM($G34:G$37)) -> 0 | H38: =IF((SUM($G$117:H117)-SUM($G34:H$37)-SUM($G$38:G38))>0,0,SUM($G$117:H117)-SUM($G34:H$37)-SUM($G38:G38)) -> 0 | I38: =IF((SUM($G$117:I117)-SUM($G34:I$37)-SUM($G$38:H38))>0,0,SUM($G$117:I117)-SUM($G34:I$37)-SUM($G38:H38)) -> -6884.4635 | J38: =IF((SUM($G$117:J117)-SUM($G34:J$37)-SUM($G$38:I38))>0,0,SUM($G$117:J117)-SUM($G34:J$37)-SUM($G38:I38)) -> -215335.94 | K38: =IF((SUM($G$117:K117)-SUM($G34:K$37)-SUM($G$38:J38))>0,0,SUM($G$117:K117)-SUM($G34:K$37)-SUM($G38:J38)) -> -414386.51 | L38: =IF((SUM($G$117:L117)-SUM($G34:L$37)-SUM($G$38:K38))>0,0,SUM($G$117:L117)-SUM($G34:L$37)-SUM($G38:K38)) -> 0 | M38: =IF((SUM($G$117:M117)-SUM($G34:M$37)-SUM($G$38:L38))>0,0,SUM($G$117:M117)-SUM($G34:M$37)-SUM($G38:L38)) -> 0 | N38: =IF((SUM($G$117:N117)-SUM($G34:N$37)-SUM($G$38:M38))>0,0,SUM($G$117:N117)-SUM($G34:N$37)-SUM($G38:M38)) -> 0 | O38: =IF((SUM($G$117:O117)-SUM($G34:O$37)-SUM($G$38:N38))>0,0,SUM($G$117:O117)-SUM($G34:O$37)-SUM($G38:N38)) -> 0 | P38: =IF((SUM($G$117:P117)-SUM($G34:P$37)-SUM($G$38:O38))>0,0,SUM($G$117:P117)-SUM($G34:P$37)-SUM($G38:O38)) -> 0 | Q38: =SUM(G38:P38) -> -636606.92
B39: Select Incetive structure option below Note: All Options include earnout of Upfront, VIK and Fixed Incentives | F39: VAT on Merchant Support | G39: =SUM(G36,G38,G34)*$C$30 -> -1246.5 | H39: =SUM(H36,H38,H34)*$C$30 -> 0 | I39: =SUM(I36,I38,I34)*$C$30 -> -190.69964 | J39: =SUM(J36,J38,J34)*$C$30 -> -5964.8057 | K39: =SUM(K36,K38,K34)*$C$30 -> -11478.506 | L39: =SUM(L36,L38,L34)*$C$30 -> 0 | M39: =SUM(M36,M38,M34)*$C$30 -> 0 | N39: =SUM(N36,N38,N34)*$C$30 -> 0 | ... P39: =SUM(P36,P38,P34)*$C$30 -> 0 | Q39: =SUM(G39:P39) -> -18880.512
E41: Net Revenue | G41: =G18+G33 -> 234347.11 | H41: =H18+H33 -> 628491.34 | I41: =I18+I33 -> 1312621.7 | J41: =J18+J33 -> 1640374.1 | K41: =K18+K33 -> 2420360.9 | L41: =L18+L33 -> 0 | M41: =M18+M33 -> 0 | N41: =N18+N33 -> 0 | ... P41: =P18+P33 -> 0 | Q41: =SUM(G41:P41) -> 6236195.1
E42: Cumulative Net Revenue | G42: =G41 -> 234347.11 | H42: =G42+H41 -> 862838.45 | I42: =H42+I41 -> 2175460.1 | J42: =I42+J41 -> 3815834.2 | K42: =J42+K41 -> 6236195.1 | L42: =K42+L41 -> 6236195.1 | M42: =L42+M41 -> 6236195.1 | N42: =M42+N41 -> 6236195.1 | O42: =N42+O41 -> 6236195.1 | P42: =O42+P41 -> 6236195.1 | Q42: =Q41 -> 6236195.1
E44: Variable Costs | G44: =G45+G46+G47 -> -2574.4745 | H44: =H45+H46+H47 -> -60173.02 | I44: =I45+I46+I47 -> -62431.966 | J44: =J45+J46+J47 -> -8257.8806 | K44: =K45+K46+K47 -> -11554.681 | L44: =L45+L46+L47 -> 0 | M44: =M45+M46+M47 -> 0 | N44: =N45+N46+N47 -> 0 | ... P44: =P45+P46+P47 -> 0 | Q44: =SUM(G44:P44) -> -144992.02
F45: Auth | G45: =-G$7*G$64 -> -1370.6357 | H45: =-H$7*H$64 -> -2088.5938 | I45: =-I$7*I$64 -> -3291.2441 | J45: =-J$7*J$64 -> -4396.4491 | K45: =-K$7*K$64 -> -6151.6469 | L45: =-L$7*L$64 -> 0 | M45: =-M$7*M$64 -> 0 | N45: =-N$7*N$64 -> 0 | ... P45: =-P$7*P$64 -> 0 | Q45: =SUM(G45:P45) -> -17298.57
...
