Workbook
Name AccrualsTemplate: "Button 12"
Name AcquirerAFTFees: [1]Schedules!#REF!
Name AcquirerFeeOptions: [1]Automation!#REF!
Name AcquirerOCTFees: [1]Schedules!#REF!
Name Activity: "Button 59"
Name AddressNoticeAddress: [1]Automation!#REF!
Name AFT: '[1]Dropdown Logic'!$AM$5:$AM$13
Name ApprovalRoute: '[1]MI Database Template'!$P$9:$P$14
Name dcDaysInWeek: 7
Name dcDaysInYear: 365
Name dcMthsInQtr: 3
Name dcMthsInYear: 12
Name dcQtrsInYear: 4
Name dcWeeksInYear: 52
Name DetailedOpenPurchaseOrderListing: "Button 11"
Name DetailedTransactionListings: "Button 9"
Name dMthsInYear: 12
Name FastTrack: [1]Automation!#REF!
Name GraphCumulativeSpend: "Button 5"
Name GraphPhasedSpend: "Button 3"
Name GraphYTDSpendByCategory: "Button 6"
Name HeadlineCategory: "Button 2"
Name Incentive_Options: 'P&L'!$E$108:$E$113
Name Last_Row: #N/A
Name Model: '[2]1b) Forecast Inputs '!$C$4
Name NoticeAddress: [1]Automation!#REF!
Name Number_of_Payments: #N/A
Name OCT: '[1]Dropdown Logic'!$AN$5:$AN$21
Name Payment_Date: #N/A
Name Phased: "Button 61"
Name PhasedReportsActByAccount: "Button 8"
Name Print_Area_Reset: #N/A
Name rtrtrr: #N/A
Name ss: #N/A
Name StrategicPricingPresent: [1]Automation!#REF!
Name TableName: "Dummy"
Name TM1REBUILDOPTION: 0
Name Values_Entered: #N/A
Name VersNo: 0.22
Name YTDVarianceKey: "Object 4"

Sheet Intro
A1: Model Version | C1: ='[1]Change Control'!C11 -> vJun24 eff 01/07/2024
B2: Please fill all cells in Yellow | D2: Opportunity ID (OPP-000XXXXXX) | E2: OPP-001060809 | F2: Deal Owner (AE) | G2: Emma Attali | H2: Scenario Name | I2: MLS | K2: Deal Checks Please ensure all checks are green | N2: Include Reason if exception
B3: Client Name | C3: Trading212 CKO LA | D3: Primary Market | E3: UK | F3: Cluster | G3: =IFERROR(VLOOKUP($E$3,'[1]Deals Database'!$B$12:$C$60,2,0),"") -> UK + Eire | H3: CI Ref (Finance to complete) | I3: FY25_421
B4: Executive Summary: (Background - Overview of Client & Business Opportunity - What has triggered this request?)
B5: Checkout is bringing to Visa a list of 15 new merchants representing an annual incremental PV of €55BN for Visa Checkout has provided information on volumes from existing merchants that Visa does not capture today, representing an annual incremental PV of €29BN for Visa. | K5: Within Fast Track | L5: =IF(COUNTIF($L$7:$L$15,"No")>0,"No","Yes") -> Yes
B6: Alignment with VE Corporate goals: (How does this deal support VE’s corporate goals? )
B7: Increase PV volumes on card rails - Capture incremental PV and net revenues for Visa. | K7: Upfront <$250K | L7: =IF(-'P&L'!$G$34*Inputs!$O$1<=250000,"Yes","No") -> Yes
B8: Win / Retain Strategy (What is the sales strategy? - Idea of what the amount and structure of incentives & Client request?) | C8: 0 | D8: 0 | E8: 0 | F8: 0 | G8: 0 | H8: 0 | I8: 0
B9: Winning new business with CKO and Liquid Assets merchants Retaining key liquid assets merchants such as Interactive Investors whose volumes are declining (-46% from 2025 to 2024) | K9: Incentive Earn-Through and Contribution B/E by Year 3 | L9: =IF(OR(SUM('P&L'!G37:I37)<=0,SUM('P&L'!G74:I74)<1),"Yes","No") -> Yes
B10: Key Benefits (What are the key reasons for approval?) | C10: 0 | D10: 0 | E10: 0 | F10: 0 | G10: 0 | H10: 0 | I10: 0
B11: Incremental PV / Net revenues for Visa and issuers (on new merchants to card rails) Supporting CKO to retain volumes on card rails with key merchants moving away from card rails because of AFT Pricing uncapped in that sector | K11: Discount on Core Fees <=35% | L11: =IF(-'P&L'!C29<=35%,"Yes","No") -> Yes
B12: Key Commercial Concerns (What are the key concerns about this opportunity?)
K13: Total Incenitves excl. IRR VAT < $10M | L13: =IF(-('P&L'!Q33-'P&L'!Q38)<10000000/Inputs!O1,"Yes","No") -> Yes | N13: Provide exception why this deal should be within Fast Track
B14: What other factors should be considered? (Concerns about the client?) | C14: 0 | D14: 0 | E14: 0 | F14: 0 | G14: 0 | H14: 0 | I14: 0
K15: Upfront < 25% of Total Incentives | L15: =IF('P&L'!Q34>='P&L'!Q33*0.25,"Yes","No") -> Yes
B17: Please complete the following for Contract Management: | F17: Please complete the following Client information:
B18: Deal Term | D18: 2 | E18: =IF(D18="","Mandatory","") | F18: Client Full Name
B19: Any existing VD portfolio under contract? | D19: Yes | F19: Client Address
B20: If existing, when does the contract end? | D20: mm/yyyy | F20: Client Notice Address
B21: Start Date for the new deal (qtr beginning) | D21: 45931 | E21: =IF(D21="","Mandatory","") | F21: CW Number
B22: End Date for the new deal (qtr ending) | D22: =IFERROR(EOMONTH(D21-1,'P&L'!C15*12),"") -> 46660 | F22: FY Number | H22: =I3 -> FY25_421
B23: Break clause year (if any) | D23: 0 | F23: BID Identifier
B24: Microsoft Dynamics Ref (OPP-000XXXXXX) | D24: =E2 -> OPP-001060809
B25: Market Name (or Pan EU)? | D25: =Intro!E3 -> UK
B28: Sharepoint folder link for model and VDDR deck: | E28: https://visainc.sharepoint.com/:f:/r/sites/VDWPricingTemplateGroup/Shared%20Documents/AE%20Intake%20Form%20(VDC)?csf=1&web=1&e=shDlBz
B29: Link for AFT Money Load Program | E29: https://visa.highspot.com/items/64b7ed48d004140237384d7a
B30: Link for OCT Strategic Alliance Fee Program | E30: https://visa.highspot.com/items/64b7ed7e2b4f9c04ea94b456

Sheet P&L
F2: Option 1 (Input Flat Discount %, excludes AFT) | G2: 0 | H2: Option 1: Flat % discount on all core OCT fees (AFTs excluded), Max 35%. For small deals cap at 25% | J2: Option 2: Tiered XB Discount on XB OCTs only (refer to tiering Table) - standard tier table | L2: Option 3: Tiered % Discount on All OCTs, tiering by DOM/Intra and XB | N2: Enterprie Adj. AANR | O2: =(Q40+Q46)/Intro!D18 -> 462077 | P2: =O2*Inputs!O1 -> 514522.74 | Q2: EU VD Only Adj. AANR | R2: =SUM(Q19:Q25,Q33,Q46)/Intro!D18 -> 346885 | S2: =R2*Inputs!O1 -> 386256.45
F3: OCT Txn % | G3: =IFERROR(1-G4,"") -> 0 | H3: =IFERROR(1-H4,"") -> 0 | I3: =IFERROR(1-I4,"") | J3: =IFERROR(1-J4,"") | K3: =IFERROR(1-K4,"") | L3: =IFERROR(1-L4,"") | M3: =IFERROR(1-M4,"") | N3: =IFERROR(1-N4,"") | ... P3: =IFERROR(1-P4,"")
C4: =IFERROR(IF(AND(Intro!D22<>"", Intro!D21<>"", C15<>""), IF(ABS(DATEDIF(Intro!D21,Intro!D22,"D") - C15*365.25) > 5, "DATE ERROR",""),""),"Check Start/End Qtr") | F4: AFT Txn % | G4: =IFERROR(Inputs!E52/Inputs!E65,"") -> 1 | H4: =IFERROR(Inputs!F52/Inputs!F65,"") -> 1 | I4: =IFERROR(Inputs!G52/Inputs!G65,"") | J4: =IFERROR(Inputs!H52/Inputs!H65,"") | K4: =IFERROR(Inputs!I52/Inputs!I65,"") | L4: =IFERROR(Inputs!J52/Inputs!J65,"") | M4: =IFERROR(Inputs!K52/Inputs!K65,"") | N4: =IFERROR(Inputs!L52/Inputs!L65,"") | ... Q4: =IFERROR(Inputs!O52/Inputs!O65,"") -> 1
F5: Total | G5: 1 | H5: 2 | I5: 3 | J5: 4 | K5: 5 | L5: 6 | M5: 7 | N5: 8 | O5: 9 | P5: 10 | Q5: Total
F6: PV - Total EUROS | G6: =Inputs!E59 -> 1047200000 | H6: =Inputs!F59 -> 1047200000 | I6: =Inputs!G59 -> 0 | J6: =Inputs!H59 -> 0 | K6: =Inputs!I59 -> 0 | L6: =Inputs!J59 -> 0 | M6: =Inputs!K59 -> 0 | N6: =Inputs!L59 -> 0 | ... P6: =Inputs!N59 -> 0 | Q6: =SUM(G6:P6) -> 2094400000 | S6: =Q6=Q9+Q12+Q15 -> TRUE
F7: Transactions - Total | G7: =Inputs!E65 -> 6545000 | H7: =Inputs!F65 -> 6545000 | I7: =Inputs!G65 -> 0 | J7: =Inputs!H65 -> 0 | K7: =Inputs!I65 -> 0 | L7: =Inputs!J65 -> 0 | M7: =Inputs!K65 -> 0 | N7: =Inputs!L65 -> 0 | ... P7: =Inputs!N65 -> 0 | Q7: =SUM(G7:P7) -> 13090000 | S7: =Q7=Q10+Q13+Q16 -> TRUE
E9: PV and Volumes | F9: PV - EU Dom | G9: =Inputs!E60 -> 1047200000 | H9: =Inputs!F60 -> 1047200000 | I9: =Inputs!G60 -> 0 | J9: =Inputs!H60 -> 0 | K9: =Inputs!I60 -> 0 | L9: =Inputs!J60 -> 0 | M9: =Inputs!K60 -> 0 | N9: =Inputs!L60 -> 0 | ... P9: =Inputs!N60 -> 0 | Q9: =SUM(G9:P9) -> 2094400000 | S9: =Q9=Inputs!O60 -> TRUE
F10: Transactions - EU Dom | G10: =Inputs!E66 -> 6545000 | H10: =Inputs!F66 -> 6545000 | I10: =Inputs!G66 -> 0 | J10: =Inputs!H66 -> 0 | K10: =Inputs!I66 -> 0 | L10: =Inputs!J66 -> 0 | M10: =Inputs!K66 -> 0 | N10: =Inputs!L66 -> 0 | ... P10: =Inputs!N66 -> 0 | Q10: =SUM(G10:P10) -> 13090000 | S10: =Q10=Inputs!O66 -> TRUE
F12: PV - EU Intra (EEA + NON-EEA) | G12: =Inputs!E61 -> 0 | H12: =Inputs!F61 -> 0 | I12: =Inputs!G61 -> 0 | J12: =Inputs!H61 -> 0 | K12: =Inputs!I61 -> 0 | L12: =Inputs!J61 -> 0 | M12: =Inputs!K61 -> 0 | N12: =Inputs!L61 -> 0 | ... P12: =Inputs!N61 -> 0 | Q12: =SUM(G12:P12) -> 0 | S12: =Q12=Inputs!O61+Inputs!O62 -> TRUE
F13: Transactions - EU Intra | G13: =Inputs!E67+Inputs!E68 -> 0 | H13: =Inputs!F67+Inputs!F68 -> 0 | I13: =Inputs!G67+Inputs!G68 -> 0 | J13: =Inputs!H67+Inputs!H68 -> 0 | K13: =Inputs!I67+Inputs!I68 -> 0 | L13: =Inputs!J67+Inputs!J68 -> 0 | M13: =Inputs!K67+Inputs!K68 -> 0 | N13: =Inputs!L67+Inputs!L68 -> 0 | ... P13: =Inputs!N67+Inputs!N68 -> 0 | Q13: =SUM(G13:P13) -> 0 | S13: =Q13=Inputs!O67+Inputs!O68 -> TRUE
B14: Deal KPIs (EUROS)
B15: Term of Contract (years) | C15: =Inputs!I3 -> 2 | F15: PV - XB | G15: =Inputs!E63+Inputs!E62 -> 0 | H15: =Inputs!F63+Inputs!F62 -> 0 | I15: =Inputs!G63+Inputs!G62 -> 0 | J15: =Inputs!H63+Inputs!H62 -> 0 | K15: =Inputs!I63+Inputs!I62 -> 0 | L15: =Inputs!J63+Inputs!J62 -> 0 | M15: =Inputs!K63+Inputs!K62 -> 0 | N15: =Inputs!L63+Inputs!L62 -> 0 | ... P15: =Inputs!N63+Inputs!N62 -> 0 | Q15: =SUM(G15:P15) -> 0 | S15: =Q15=Inputs!O63 -> TRUE
B16: Total Transactions | C16: =Inputs!O65 -> 13090000 | F16: Transactions - XB | G16: =Inputs!E69+Inputs!E68 -> 0 | H16: =Inputs!F69+Inputs!F68 -> 0 | I16: =Inputs!G69+Inputs!G68 -> 0 | J16: =Inputs!H69+Inputs!H68 -> 0 | K16: =Inputs!I69+Inputs!I68 -> 0 | L16: =Inputs!J69+Inputs!J68 -> 0 | M16: =Inputs!K69+Inputs!K68 -> 0 | N16: =Inputs!L69+Inputs!L68 -> 0 | ... P16: =Inputs!N69+Inputs!N68 -> 0 | Q16: =SUM(G16:P16) -> 0 | S16: =Q16=SUM(Inputs!O68:O69) -> TRUE
B17: Average Annualised Tranactions | C17: =IFERROR(C16/C15,0) -> 6545000
B18: DOM Txn% | C18: =IFERROR(Inputs!P66,"check") -> 1 | E18: Fees/revenue | F18: Gross Revenue (OCT+AFT) | G18: =SUM(G19:G32) -> 464695 | H18: =SUM(H19:H32) -> 459459 | I18: =SUM(I19:I32) -> 0 | J18: =SUM(J19:J32) -> 0 | K18: =SUM(K19:K32) -> 0 | L18: =SUM(L19:L32) -> 0 | M18: =SUM(M19:M32) -> 0 | N18: =SUM(N19:N32) -> 0 | ... P18: =SUM(P19:P32) -> 0 | Q18: =SUM(G18:P18) -> 924154
B19: INTRA EEA Txn% | C19: =IFERROR(Inputs!P67,"check") -> 0 | F19: Acq Processing Rev - EU Dom | G19: =[1]Calcs!AY68 -> 53669 | H19: =[1]Calcs!AZ68 -> 53669 | I19: =[1]Calcs!BA68 -> 0 | J19: =[1]Calcs!BB68 -> 0 | K19: =[1]Calcs!BC68 -> 0 | L19: =[1]Calcs!BD68 -> 0 | M19: =[1]Calcs!BE68 -> 0 | N19: =[1]Calcs!BF68 -> 0 | ... P19: =[1]Calcs!BH68 -> 0 | Q19: =SUM(G19:P19) -> 107338
B20: INTRA Non-EEA Txn% | C20: =IFERROR(Inputs!P68,"check") -> 0 | F20: Acq Scheme Rev - EU Dom | G20: =[1]Calcs!AN68 -> 293216 | H20: =[1]Calcs!AO68 -> 293216 | I20: =[1]Calcs!AP68 -> 0 | J20: =[1]Calcs!AQ68 -> 0 | K20: =[1]Calcs!AR68 -> 0 | L20: =[1]Calcs!AS68 -> 0 | M20: =[1]Calcs!AT68 -> 0 | N20: =[1]Calcs!AU68 -> 0 | ... P20: =[1]Calcs!AW68 -> 0 | Q20: =SUM(G20:P20) -> 586432
B21: Inter Txn% | C21: =IFERROR(Inputs!P69,"check") -> 0
B22: Total Core Acquiring Fees | C22: =SUM(G19:P25) -> 693770 | F22: Acq Processing Rev - EU Intra | G22: =[1]Calcs!AY69 -> 0 | H22: =[1]Calcs!AZ69 -> 0 | I22: =[1]Calcs!BA69 -> 0 | J22: =[1]Calcs!BB69 -> 0 | K22: =[1]Calcs!BC69 -> 0 | L22: =[1]Calcs!BD69 -> 0 | M22: =[1]Calcs!BE69 -> 0 | N22: =[1]Calcs!BF69 -> 0 | ... P22: =[1]Calcs!BH69 -> 0 | Q22: =SUM(G22:P22) -> 0
B23: Total Gross Revenue | C23: =Q18 -> 924154 | F23: Acq Scheme Rev - EU Intra | G23: =[1]Calcs!AN69 -> 0 | H23: =[1]Calcs!AO69 -> 0 | I23: =[1]Calcs!AP69 -> 0 | J23: =[1]Calcs!AQ69 -> 0 | K23: =[1]Calcs!AR69 -> 0 | L23: =[1]Calcs!AS69 -> 0 | M23: =[1]Calcs!AT69 -> 0 | N23: =[1]Calcs!AU69 -> 0 | ... P23: =[1]Calcs!AW69 -> 0 | Q23: =SUM(G23:P23) -> 0
B24: Total Incentives incl IRR VAT | C24: =Q33 -> 0
B25: Total Net Revenue | C25: =IFERROR(Q40,0) -> 924154 | F25: Acquirer Rev - XB | G25: =SUM([1]Calcs!AN70:AN71,[1]Calcs!AY70:AY71) -> 0 | H25: =SUM([1]Calcs!AO70:AO71,[1]Calcs!AZ70:AZ71) -> 0 | I25: =SUM([1]Calcs!AP70:AP71,[1]Calcs!BA70:BA71) -> 0 | J25: =SUM([1]Calcs!AQ70:AQ71,[1]Calcs!BB70:BB71) -> 0 | K25: =SUM([1]Calcs!AR70:AR71,[1]Calcs!BC70:BC71) -> 0 | L25: =SUM([1]Calcs!AS70:AS71,[1]Calcs!BD70:BD71) -> 0 | M25: =SUM([1]Calcs!AT70:AT71,[1]Calcs!BE70:BE71) -> 0 | N25: =SUM([1]Calcs!AU70:AU71,[1]Calcs!BF70:BF71) -> 0 | ... P25: =SUM([1]Calcs!AW70:AW71,[1]Calcs!BH70:BH71) -> 0 | Q25: =SUM(G25:P25) -> 0 | S25: =SUM(Q20:Q25) -> 586432
B26: AANR | C26: =IFERROR(C25/C15,0) -> 462077 | F26: Issuer Rev (All Volumes) | G26: =G72 -> 52360 | H26: =H72 -> 47124 | I26: =I72 -> 0 | J26: =J72 -> 0 | K26: =K72 -> 0 | L26: =L72 -> 0 | M26: =M72 -> 0 | N26: =N72 -> 0 | ... P26: =P72 -> 0 | Q26: =SUM(G26:P26) -> 99484
B27: AANR excl VTS | C27: =(Q40-Q32)/C15 -> 396627 | F27: Other Fees (e.g. Alias Directory) | Q27: =SUM(G27:P27) -> 0
B28: Incentive $ of Gross Rev. incl VAT | C28: =IFERROR(C24/C23,0) -> 0 | F28: VIK Revenues | G28: =-G36/1.2 -> 0 | H28: =-H36/1.2 -> 0 | I28: =-I36/1.2 -> 0 | J28: =-J36/1.2 -> 0 | K28: =-K36/1.2 -> 0 | L28: =-L36/1.2 -> 0 | M28: =-M36/1.2 -> 0 | N28: =-N36/1.2 -> 0 | ... P28: =-P36/1.2 -> 0 | Q28: =SUM(G28:P28) -> 0
B29: Incentive $ of Core Fees excl IRR VAT | C29: =IFERROR((C24-Q38)/C22,0) -> 0 | F29: FX Spread - Inter | G29: =[1]Calcs!BJ71 -> 0 | H29: =[1]Calcs!BK71 -> 0 | I29: =[1]Calcs!BL71 -> 0 | J29: =[1]Calcs!BM71 -> 0 | K29: =[1]Calcs!BN71 -> 0 | L29: =[1]Calcs!BO71 -> 0 | M29: =[1]Calcs!BP71 -> 0 | N29: =[1]Calcs!BQ71 -> 0 | ... P29: =[1]Calcs!BS71 -> 0 | Q29: =SUM(G29:P29) -> 0
B30: IRR VAT Rate | C30: 0.0277 | F30: FX Spread - Intra | G30: =[1]Calcs!BJ69+[1]Calcs!BJ70 -> 0 | H30: =[1]Calcs!BK69+[1]Calcs!BK70 -> 0 | I30: =[1]Calcs!BL69+[1]Calcs!BL70 -> 0 | J30: =[1]Calcs!BM69+[1]Calcs!BM70 -> 0 | K30: =[1]Calcs!BN69+[1]Calcs!BN70 -> 0 | L30: =[1]Calcs!BO69+[1]Calcs!BO70 -> 0 | M30: =[1]Calcs!BP69+[1]Calcs!BP70 -> 0 | N30: =[1]Calcs!BQ69+[1]Calcs!BQ70 -> 0 | ... P30: =[1]Calcs!BS69+[1]Calcs!BS70 -> 0 | Q30: =SUM(G30:P30) -> 0
B31: IRR VAT Rate | C31: 0.0277 | F31: Visa+ | G31: =SUM([1]Calcs!AC84,[1]Calcs!AC90)*[1]Calcs!$B$4 -> 0 | H31: =SUM([1]Calcs!AD84,[1]Calcs!AD90)*[1]Calcs!$B$4 -> 0 | I31: =SUM([1]Calcs!AE84,[1]Calcs!AE90)*[1]Calcs!$B$4 -> 0 | J31: =SUM([1]Calcs!AF84,[1]Calcs!AF90)*[1]Calcs!$B$4 -> 0 | K31: =SUM([1]Calcs!AG84,[1]Calcs!AG90)*[1]Calcs!$B$4 -> 0 | L31: =SUM([1]Calcs!AH84,[1]Calcs!AH90)*[1]Calcs!$B$4 -> 0 | M31: =SUM([1]Calcs!AI84,[1]Calcs!AI90)*[1]Calcs!$B$4 -> 0 | N31: =SUM([1]Calcs!AJ84,[1]Calcs!AJ90)*[1]Calcs!$B$4 -> 0 | ... P31: =SUM([1]Calcs!AL84,[1]Calcs!AL90)*[1]Calcs!$B$4 -> 0 | Q31: =SUM(G31:P31) -> 0
B32: Deal Breakeven | C32: =Q74 -> 1 | F32: Delegated Auth Fees (3DS/VTS) | G32: =Inputs!E52*[1]Calcs!$B$3 -> 65450 | H32: =Inputs!F52*[1]Calcs!$B$3 -> 65450 | I32: =Inputs!G52*[1]Calcs!$B$3 -> 0 | J32: =Inputs!H52*[1]Calcs!$B$3 -> 0 | K32: =Inputs!I52*[1]Calcs!$B$3 -> 0 | L32: =Inputs!J52*[1]Calcs!$B$3 -> 0 | M32: =Inputs!K52*[1]Calcs!$B$3 -> 0 | N32: =Inputs!L52*[1]Calcs!$B$3 -> 0 | ... P32: =Inputs!N52*[1]Calcs!$B$3 -> 0 | Q32: =SUM(G32:P32) -> 130900 | R32: =G20/G10 -> 0.0448 | S32: =H20/H10 -> 0.0448 | T32: =I20/I10 -> #DIV/0!
B33: Upfront | C33: =Q34 -> 0 | E33: Incentives | F33: Total Incentives (incl VAT) | G33: =SUM(G34:G38) -> 0 | H33: =SUM(H34:H38) -> 0 | I33: =SUM(I34:I38) -> 0 | J33: =SUM(J34:J38) -> 0 | K33: =SUM(K34:K38) -> 0 | L33: =SUM(L34:L38) -> 0 | M33: =SUM(M34:M38) -> 0 | N33: =SUM(N34:N38) -> 0 | ... Q33: =SUM(Q34:Q38) -> 0
B34: Fixed Support | C34: =Q35+Q36 -> 0 | F34: Upfront (Max $250k incl VAT) - earned out | Q34: =SUM(G34:P34) -> 0
B35: Volume Support | C35: =Q37 -> 0 | F35: Fixed Support - earned out | Q35: =SUM(G35:P35) -> 0
B36: Total Incentive Value | C36: =SUM(C33:C35) -> 0 | F36: VIK Support (Gross, including VAT) - earned out | Q36: =SUM(G36:P36) -> 0
B37: Please review the RED cells as these indicate an error | F37: Volume Support (milestone based) | G37: =IF((0.06*G10)-G20>0,0,(0.06*G10)-G20) -> 0 | H37: =IF((0.06*H10)-H20>0,0,(0.06*H10)-H20) -> 0 | I37: =(0.06*I10)-I20 -> 0 | J37: =(0.05*J10)-J20 -> 0 | K37: =(0.05*K10)-K20 -> 0 | L37: =(0.05*L10)-L20 -> 0 | Q37: =SUM(G37:P37) -> 0
B38: Select Incetive structure option below Note: All Options include earnout of Upfront, VIK and Fixed Incentives | F38: VAT on Merchant Support | G38: =SUM(G34:G35,G37)*$C$30 -> 0 | H38: =SUM(H34:H35,H37)*$C$30 -> 0 | I38: =SUM(I34:I35,I37)*$C$30 -> 0 | J38: =SUM(J34:J35,J37)*$C$30 -> 0 | K38: =SUM(K34:K35,K37)*$C$30 -> 0 | L38: =SUM(L34:L35,L37)*$C$30 -> 0 | M38: =SUM(M34:M35,M37)*$C$30 -> 0 | N38: =SUM(N34:N35,N37)*$C$30 -> 0 | ... P38: =SUM(P34:P35,P37)*$C$30 -> 0 | Q38: =SUM(G38:P38) -> 0
E40: Net Revenue | G40: =G18+G33 -> 464695 | H40: =H18+H33 -> 459459 | I40: =I18+I33 -> 0 | J40: =J18+J33 -> 0 | K40: =K18+K33 -> 0 | L40: =L18+L33 -> 0 | M40: =M18+M33 -> 0 | N40: =N18+N33 -> 0 | ... P40: =P18+P33 -> 0 | Q40: =SUM(G40:P40) -> 924154
E41: Cumulative Net Revenue | G41: =G40 -> 464695 | H41: =G41+H40 -> 924154 | I41: =H41+I40 -> 924154 | J41: =I41+J40 -> 924154 | K41: =J41+K40 -> 924154 | L41: =K41+L40 -> 924154 | M41: =L41+M40 -> 924154 | N41: =M41+N40 -> 924154 | O41: =N41+O40 -> 924154 | P41: =O41+P40 -> 924154 | Q41: =Q40 -> 924154
E43: Variable Costs | G43: =G44+G45+G46 -> -17167.535 | H43: =H44+H45+H46 -> -15838.9 | I43: =I44+I45+I46 -> 0 | J43: =J44+J45+J46 -> 0 | K43: =K44+K45+K46 -> 0 | L43: =L44+L45+L46 -> 0 | M43: =M44+M45+M46 -> 0 | N43: =N44+N45+N46 -> 0 | ... P43: =P44+P45+P46 -> 0 | Q43: =SUM(G43:P43) -> -33006.435
F44: Auth | G44: =-G$7*G$63 -> -9139.8989 | H44: =-H$7*H$63 -> -8432.5411 | I44: =-I$7*I$63 -> 0 | J44: =-J$7*J$63 -> 0 | K44: =-K$7*K$63 -> 0 | L44: =-L$7*L$63 -> 0 | M44: =-M$7*M$63 -> 0 | N44: =-N$7*N$63 -> 0 | ... P44: =-P$7*P$63 -> 0 | Q44: =SUM(G44:P44) -> -17572.44
F45: C&S | G45: =-G$7*G$64 -> -8027.6361 | H45: =-H$7*H$64 -> -7406.3589 | I45: =-I$7*I$64 -> 0 | J45: =-J$7*J$64 -> 0 | K45: =-K$7*K$64 -> 0 | L45: =-L$7*L$64 -> 0 | M45: =-M$7*M$64 -> 0 | N45: =-N$7*N$64 -> 0 | ... P45: =-P$7*P$64 -> 0 | Q45: =SUM(G45:P45) -> -15433.995 | S45: =0.034*0.8 -> 0.0272
...

Sheet Inputs
A1: EEA | B1: INTRA EEA | D1: Modelling Assumptions | F1: Mandatory Fields | J1: Optional Fields | N1: FX EUR/USD | O1: 1.1135 | R1: Guidance on completing input sheet: 1. Please fill in cells highlighted in Yellow - INPUT in EUROS 2. Please select the Market from the drop down. If multiple markets, please select the biggest market for the opportunity. 3. UK/IS/CH/TK to rest of EU is Intra NON-EEA Transaction (also vice versa). If modelling for UK/IS/CH/TK, there will not be any Intra EEA transactions.
A2: UK | B2: Intra NonEEA
A3: Turkey | F3: Origin Market | G3: =VLOOKUP(Intro!$E$3,[1]Metrics!$B$114:$D$156,3,0) -> UK | H3: Term | I3: =Intro!D18 -> 2 | N3: FX EUR/GBP | O3: 0.83252336
A4: Israel | F4: Client Type | G4: Enabler | H4: AFT IRF | I4: MLP T2 | J4: Please select one option or "Rack"
A5: Switzerland | F5: =IF($G$4="Originator","Input Enabler Name","") | G5: TBC | H5: OCT IRF | I5: Rack | J5: Please select one option or "Rack"
D7: Destination | E7: Average Ticket Size
E8: OCT - PP & AA | F8: OCT - FD | G8: AFT | H8: Cross Curr % | I8: Credit % | J8: Debit %
A9: =$G$3&D9 -> UKDOM | D9: DOM | G9: 160 | J9: =1-I9 -> 1
A10: =$G$3&D10 -> UKINTRA EEA | D10: INTRA EEA | H10: 0.1 | J10: =1-I10 -> 1
A11: =$G$3&D11 -> UKINTRA Non-EEA | D11: INTRA Non-EEA | H11: 0.65 | J11: =1-I11 -> 1
A12: =$G$3&D12 -> UKINTER | D12: INTER | H12: 0.65 | J12: =1-I12 -> 1
A17: Mapping Table - Do not change/delete | D17: Input Number of Transactions by Jurisdiction in Yellow Cells
E18: =IF(E19<=$I$3,1,0) -> 1 | F18: =IF(F19<=$I$3,1,0) -> 1 | G18: =IF(G19<=$I$3,1,0) -> 0 | H18: =IF(H19<=$I$3,1,0) -> 0 | I18: =IF(I19<=$I$3,1,0) -> 0 | J18: =IF(J19<=$I$3,1,0) -> 0 | K18: =IF(K19<=$I$3,1,0) -> 0 | L18: =IF(L19<=$I$3,1,0) -> 0 | ... O18: =IF(O19<=$I$3,1,0) -> 0
D19: OCT - PP & AA | E19: 1 | F19: 2 | G19: 3 | H19: 4 | I19: 5 | J19: 6 | K19: 7 | L19: 8 | M19: 9 | N19: 10 | O19: Total
D20: Total PV | E20: =SUM(E21:E24) -> 0 | F20: =SUM(F21:F24) -> 0 | G20: =SUM(G21:G24) -> 0 | H20: =SUM(H21:H24) -> 0 | I20: =SUM(I21:I24) -> 0 | J20: =SUM(J21:J24) -> 0 | K20: =SUM(K21:K24) -> 0 | L20: =SUM(L21:L24) -> 0 | ... N20: =SUM(N21:N24) -> 0 | O20: =SUM(E20:N20) -> 0
D21: DOM | E21: =E27*$E9 -> 0 | F21: =F27*$E9 -> 0 | G21: =G27*$E9 -> 0 | H21: =H27*$E9 -> 0 | I21: =I27*$E9 -> 0 | J21: =J27*$E9 -> 0 | K21: =K27*$E9 -> 0 | L21: =L27*$E9 -> 0 | ... N21: =N27*$E9 -> 0 | O21: =SUM(E21:N21) -> 0
D22: INTRA EEA | E22: =E28*$E10 -> 0 | F22: =F28*$E10 -> 0 | G22: =G28*$E10 -> 0 | H22: =H28*$E10 -> 0 | I22: =I28*$E10 -> 0 | J22: =J28*$E10 -> 0 | K22: =K28*$E10 -> 0 | L22: =L28*$E10 -> 0 | ... N22: =N28*$E10 -> 0 | O22: =SUM(E22:N22) -> 0
D23: INTRA Non-EEA | E23: =E29*$E11 -> 0 | F23: =F29*$E11 -> 0 | G23: =G29*$E11 -> 0 | H23: =H29*$E11 -> 0 | I23: =I29*$E11 -> 0 | J23: =J29*$E11 -> 0 | K23: =K29*$E11 -> 0 | L23: =L29*$E11 -> 0 | ... N23: =N29*$E11 -> 0 | O23: =SUM(E23:N23) -> 0
D24: INTER | E24: =E30*$E12 -> 0 | F24: =F30*$E12 -> 0 | G24: =G30*$E12 -> 0 | H24: =H30*$E12 -> 0 | I24: =I30*$E12 -> 0 | J24: =J30*$E12 -> 0 | K24: =K30*$E12 -> 0 | L24: =L30*$E12 -> 0 | ... N24: =N30*$E12 -> 0 | O24: =SUM(E24:N24) -> 0
R25: Choose Main and Detailed Use Case for OCT P2P | T25: Secondary (BAI) | U25: Tertiary BAI
D26: Total Transactions | E26: =SUM(E27:E30) -> 0 | F26: =SUM(F27:F30) -> 0 | G26: =SUM(G27:G30) -> 0 | H26: =SUM(H27:H30) -> 0 | I26: =SUM(I27:I30) -> 0 | J26: =SUM(J27:J30) -> 0 | K26: =SUM(K27:K30) -> 0 | L26: =SUM(L27:L30) -> 0 | ... N26: =SUM(N27:N30) -> 0 | O26: =SUM(E26:N26) -> 0 | P26: =O26/SUM($O$26+$O$39+$O$52) -> 0
A27: =$G$3&$D$19&D27 -> UKOCT - PP & AADOM | D27: DOM | O27: =SUM(E27:N27) -> 0
A28: =$G$3&$D$19&D28 -> UKOCT - PP & AAINTRA EEA | D28: INTRA EEA | O28: =SUM(E28:N28) -> 0
A29: =$G$3&$D$19&D29 -> UKOCT - PP & AAINTRA Non-EEA | D29: INTRA Non-EEA | O29: =SUM(E29:N29) -> 0
A30: =$G$3&$D$19&D30 -> UKOCT - PP & AAINTER | D30: INTER | O30: =SUM(E30:N30) -> 0
D32: OCT - FD | E32: 1 | F32: 2 | G32: 3 | H32: 4 | I32: 5 | J32: 6 | K32: 7 | L32: 8 | M32: 9 | N32: 10 | O32: Total
D33: Total PV | E33: =SUM(E34:E37) -> 0 | F33: =SUM(F34:F37) -> 0 | G33: =SUM(G34:G37) -> 0 | H33: =SUM(H34:H37) -> 0 | I33: =SUM(I34:I37) -> 0 | J33: =SUM(J34:J37) -> 0 | K33: =SUM(K34:K37) -> 0 | L33: =SUM(L34:L37) -> 0 | ... N33: =SUM(N34:N37) -> 0 | O33: =SUM(E33:N33) -> 0
D34: DOM | E34: =E40*$F9 -> 0 | F34: =F40*$F9 -> 0 | G34: =G40*$F9 -> 0 | H34: =H40*$F9 -> 0 | I34: =I40*$F9 -> 0 | J34: =J40*$F9 -> 0 | K34: =K40*$F9 -> 0 | L34: =L40*$F9 -> 0 | ... N34: =N40*$F9 -> 0 | O34: =SUM(E34:N34) -> 0
D35: INTRA EEA | E35: =E41*$F10 -> 0 | F35: =F41*$F10 -> 0 | G35: =G41*$F10 -> 0 | H35: =H41*$F10 -> 0 | I35: =I41*$F10 -> 0 | J35: =J41*$F10 -> 0 | K35: =K41*$F10 -> 0 | L35: =L41*$F10 -> 0 | ... N35: =N41*$F10 -> 0 | O35: =SUM(E35:N35) -> 0
D36: INTRA Non-EEA | E36: =E42*$F11 -> 0 | F36: =F42*$F11 -> 0 | G36: =G42*$F11 -> 0 | H36: =H42*$F11 -> 0 | I36: =I42*$F11 -> 0 | J36: =J42*$F11 -> 0 | K36: =K42*$F11 -> 0 | L36: =L42*$F11 -> 0 | ... N36: =N42*$F11 -> 0 | O36: =SUM(E36:N36) -> 0
D37: INTER | E37: =E43*$F12 -> 0 | F37: =F43*$F12 -> 0 | G37: =G43*$F12 -> 0 | H37: =H43*$F12 -> 0 | I37: =I43*$F12 -> 0 | J37: =J43*$F12 -> 0 | K37: =K43*$F12 -> 0 | L37: =L43*$F12 -> 0 | ... N37: =N43*$F12 -> 0 | O37: =SUM(E37:N37) -> 0
R38: Choose Main and Detailed Use Case for OCT FD | T38: Secondary (BAI) | U38: Tertiary BAI
D39: Total Transactions | E39: =SUM(E40:E43) -> 0 | F39: =SUM(F40:F43) -> 0 | G39: =SUM(G40:G43) -> 0 | H39: =SUM(H40:H43) -> 0 | I39: =SUM(I40:I43) -> 0 | J39: =SUM(J40:J43) -> 0 | K39: =SUM(K40:K43) -> 0 | L39: =SUM(L40:L43) -> 0 | ... N39: =SUM(N40:N43) -> 0 | O39: =SUM(E39:N39) -> 0 | P39: =O39/SUM($O$26+$O$39+$O$52) -> 0
A40: =$G$3&$D$32&D40 -> UKOCT - FDDOM | B40: DOM | D40: DOM | O40: =SUM(E40:N40) -> 0
A41: =$G$3&$D$32&D41 -> UKOCT - FDINTRA EEA | B41: INTRA EEA | D41: INTRA EEA | O41: =SUM(E41:N41) -> 0
A42: =$G$3&$D$32&D42 -> UKOCT - FDINTRA Non-EEA | B42: INTRA Non-EEA | D42: INTRA Non-EEA | O42: =SUM(E42:N42) -> 0
A43: =$G$3&$D$32&D43 -> UKOCT - FDINTER | B43: INTER | D43: INTER | O43: =SUM(E43:N43) -> 0
D45: AFT | E45: 1 | F45: 2 | G45: 3 | H45: 4 | I45: 5 | J45: 6 | K45: 7 | L45: 8 | M45: 9 | N45: 10 | O45: Total
D46: Total PV | E46: =SUM(E47:E50) -> 1047200000 | F46: =SUM(F47:F50) -> 1047200000 | G46: =SUM(G47:G50) -> 0 | H46: =SUM(H47:H50) -> 0 | I46: =SUM(I47:I50) -> 0 | J46: =SUM(J47:J50) -> 0 | K46: =SUM(K47:K50) -> 0 | L46: =SUM(L47:L50) -> 0 | ... N46: =SUM(N47:N50) -> 0 | O46: =SUM(E46:N46) -> 2094400000
D47: DOM | E47: =E53*$G9 -> 1047200000 | F47: =F53*$G9 -> 1047200000 | G47: =G53*$G9 -> 0 | H47: =H53*$G9 -> 0 | I47: =I53*$G9 -> 0 | J47: =J53*$G9 -> 0 | K47: =K53*$G9 -> 0 | L47: =L53*$G9 -> 0 | ... N47: =N53*$G9 -> 0 | O47: =SUM(E47:N47) -> 2094400000
...
